Workbook

Sheet Raw_data
A1: User_Id | B1: Product_ID | C1: user | D1: Date/ timestamp | E1: title | F1: extension | G1: is_helpful | H1: rating | I1: review | J1: category
A2: AH5M24Z73ZHQGN77WA3JT3Q7TEBQ | B2: PROD001 | C2: Clara | D2: 45658.158 | E2: NUWAVE, GRILL IS PRETTY GOOD SO FAR | F2: Verified Purchase | G2: 87 | H2: 5 | I2: This is a pretty good little grilling cookerIt's easy to use and clean, and with a bunch of time and temperature settings you can easily air grill all kinds of meat | J2: kitchen
A3: AFI7ALURI5CPDT4V7CUXZXLNFDVA | B3: PROD002 | C3: Wyeventer | D3: 45658.222 | E3: Game changer | F3: Verified Purchase | G3: 119 | H3: 5 | I3: I wasn't sure I needed an air fryer. I'm so glad I took the leap! | J3: kitchen
A4: AENH6LSB6BM7XLPEYUL43WBOD6JA | B4: PROD003 | C4: A | D4: 45658.447 | E4: More Than Meets My Needs | F4: Verified Purchase | G4: 87 | H4: 4 | I4: My Needs:Smallish footprint.No burns.Even cooking.Versatility.Intuitive operation or a good manual.Durability.Shouldn't be too hard, right? I had an Emerson convection toaster oven that took great care of my family for almost exactly 15 years. When it died a week ago, I looked at the counter space and thought SCORE!Then we tried to live without a toaster oven.I have a Samsung smart range that I would marry if not for my husband's objections. It does a lot and has a lot of perfectly calibrated presets. But it's a big machine that uses gas and electricity and takes a while to heat up and that's a lot to reheat a slice or a sandwich. And, even though it's a lot better insulated than the oven it replaces, it does heat the kitchen in the summer.And wouldn't you know it? Right after the toaster oven died, we had need to heat a sandwich. The dead toaster oven was oppressing us.It's a first world problem and we are first world people, but we are not made of money, and it was Presidents Day. So we bought this thing.It stays cool enough to be able to put your hand on it while it airfries. My actual air fryer will scorch you if you try laying hands on it. You can touch the sides, the top, the door, the handle. Warm? Yes. Do you harm? No.The footprint is smaller than my old one. It's small enough that I can pull it out to the end of the counter and not have it under my cabinets while it cooks.So far, it cooks perfectly evenly. Tater tots come out looking like little brown shirts or army tots, completely conforming, each to the others. The probe seems accurate.Accessories were easy to set up, but the oven operation is a bit opaque on the panel. Luckily, the manual works. It's an alleged air fryer? But there's no preset for that (you can make one if you're into operator's manual deep dives).And it's very versatile - bread proof/yogurt temp all the way up to air fry. I just lost the need for three different appliances.Hope this thing lasts. I kind of love it. | J4: kitchen
A5: AHFAAT5CJ6IIGIURHFBICP44ZHVA | B5: PROD004 | C5: Aylene W. Barr | D5: 45658.657 | E5: Great machine and incredible customer support! | F5: Verified Purchase | G5: One | H5: 5 | I5: My family is following a low carb diet and we have essentially six adults living together (MIL and adult children still here while going to college etc) so there is food being cooked at all hours of the day. This machine is used at least twice a day, sometimes five or six times a day. Crisy bacon is easy, frozen patties cooked to done and great for chicken nuggets too.We were very unhappy when I started getting an error message when preheating and worried that it might be dangerous. I looked up the online customer manual and found the error message listed there. I followed the directions and emailed customer service for help. I received a response on the same day and they sent me a replacement unit free of charge that I got in less than a week. The box includes a return shipping sticker (prepaid) to send back the defective unit. That is customer service!The new unit works great and we are back in business! | J5: kitchen
A6: AG4UMTWF2QN3BRDCSNVXTGZTPCAA | B6: PROD005 | C6: Ivette | D6: 45658.837 | E6: Love it | F6: Verified Purchase | G6: One | H6: 5 | I6: I bought this nuwave brio in November 2020. I never did a review but I want to do it know. In Nov 2025 will be 5 years using this airfryer and I can't live with out her. Perfection cooker in food, perfect rotisserie chicken, juicy red meat. The numbers in panel are intact and perfect size for my kitchen. | J6: kitchen
A7: AHO5TWX2UUDF22I2XOW4SZN2GDRQ | B7: PROD006 | C7: Djinn | D7: 45658.996 | E7: Works great! | F7: Verified Purchase | H7: 5 | I7: I love the design as well as the ease and of using it. | J7: kitchen
A8: AFKZUIF6G6FKXDFO22NL5W3ZLHUQ | B8: PROD007 | C8: Ethan | D8: 45659.039 | E8: Quiet! Hot! It has Rotisserie!! | F8: Verified Purchase | G8: 28 | H8: 5 | I8: Ok. I almost NEVER write Product reviews, but this Air Fryer absolutely blew me away (pun intended).First things first, the sound. One of the things that made me want to spend a bit more on an Air fryer than I did initially (this is my second fryer in the past few years) is the noise. My first Air fryer (about $70) was LOUD and it got annoying as I work in the room next to it. This thing comparatively makes almost no noise.Next, my favorite feature, Rotisserie. I never thought I needed this feature until I tried it. It does a REALLY good job. I am able to rotisserie two chicken breasts at the same time quite comfortably using the included basket. The chicken comes out after about 18 minutes hot, crispy and juicy!I have also done a fair amount of "bulk cooking" making an entire dinner across 3 racks for a family of 5 fairly comfortably.I haven't used the included probe yet, but having the ability to cook to temperature is exciting.Finally, the most hidden gem feature is easily the glass front and light. I can watch my food cook! Very often I am cooking something I haven't air fried before, so I don't know exactly how long I would need, and being able to watch it cook and make decisions based on what I am seeing is a game changer! | J8: kitchen
A9: AF44IYYKVBHBUNKQEICMO4T7MJ6Q | B9: PROD008 | C9: Benjamin Solheim | D9: 45659.26 | E9: Good for cheese burgers | F9: Verified Purchase | G9: One | H9: 5 | I9: I had trouble getting it to cook perogies, they either are too hard or undercooked. But cheese burgers at 350 for 4 minutes on a side for normal size patty came out a nice medium. It is a pita to clean even with the removable drip tray but not needing to use my over is nice. I've made a couple things in it I found the temps and times from youtube videos mostly. Some things are faster some things are slower but most things are similar times to a regular over. | J9: kitchen
A10: AGTVNHEOZCRUASEIU2QX6JBVWNCQ | B10: PROD009 | C10: jackie hodges | D10: 45659.377 | E10: oven | F10: Verified Purchase | H10: 5 | I10: this was a great addition to my kitchen. But it was to large for the space that i have. So I returned it | J10: kitchen
A11: AEZMHCTOR4XWPQJJEP47UBY2G4UA | B11: PROD010 | C11: gabriel | D11: 45660.153 | E11: Good | F11: Verified Purchase | H11: 4 | I11: Goog | J11: kitchen
A12: AFGOHTTJWRAYHJQKZZULDJID5ADQ | B12: PROD011 | C12: Yuki | D12: 45660.29 | E12: Great tool for busy mom | F12: Verified Purchase | G12: 48 | H12: 5 | I12: First time Apple Watch user and I am very happy with the purchase. As a mom of toddler, this is very helpful tool so that I get notification while my phone is inside stroller or diaper bag and chasing my child in the park. I also love the GPS and emergency notification that I can share with my family. I have started to work out little more and care for health as it encourage to stand up, track movement etc which is very helpful. Iâ€™m impressed with the battery life and how fast it charges too! Iâ€™ve been using iPhone since it came out and MacBook but Apple Watch was something I didnâ€™t think I needed. Itâ€™s not something you need, but it is well worth investing to make your life easier. Watch quality and size is perfect for my arm and it is durable and water resistance so I donâ€™t have to worry about it while playing in the splash pad or parks too! | J12: Electronics
A13: AFFUJJPQEWVDXYGSKC3SLMIIU75Q | B13: PROD012 | C13: Saby | D13: 45660.524 | E13: Amazing, my favorite purchase | F13: Verified Purchase | G13: 2 | H13: 5 | I13: Absolutely love this watch! Itâ€™s my first smart watch, so I decided to start with the SE and if I wanted to upgrade to the Series 9/10 I could later. But this little watch does everything I need it to. I donâ€™t work out a lot, but I enjoy using it when I dance and go on walks. I like that you can text or answer calls quickly when youâ€™re away from your phone. I have a very hands-on job, but the screen looks good, some scratches if you look reallly hard, but no large cracks. I also really like the starlight color, itâ€™s a nice warmer silver that matches more of my outfits/jewelry. Vernal, very happy with it. | J13: Electronics
A14: AEWQC7JKO4RBKIHOK3U7S7PJ5O6A | B14: PROD013 | C14: Shelby | D14: 45660.793 | E14: Daily watch | F14: Verified Purchase | G14: 3 | H14: 5 | I14: I bought this watch over a year ago and I do love it. It tracks my activity, I can talk on the phone, text back, it will even find my phone if I lose it! The battery tends to die fairly quick. I have to charge it once a day. The color is pretty and is a very durable watch. All in all, I highly recommend the Apple Watch! | J14: Electronics
A15: AHJGHJOHYP5YGMOACP4BNXQKZTIQ | B15: PROD014 | C15: Sunny dhama | D15: 45661.038 | E15: Great battery life and seamless integration! | F15: Verified Purchase | G15: 96 | H15: 5 | I15: I recently acquired the Apple Watch SE (2nd Gen) with the Starlight Aluminum Case and Starlight Sport Band, and I must say it has been a game-changer for me. As a graduate student pursuing a master's in computer science at the University of Florida and a research assistant at the Learn Dialogue Lab, I needed a smartwatch that could seamlessly integrate into my active lifestyle, help me stay on top of my health, and even assist in my research tasks. The Apple Watch SE has exceeded my expectations in all these aspects.One of the standout features for me is the fitness and sleep tracking capabilities. With my busy schedule, it's crucial to keep tabs on my physical activity and sleep patterns. The Apple Watch SE does an excellent job of tracking my steps, calories burned, and even encourages me to move when I've been sitting for too long. The sleep tracking feature has been a revelation, providing insights into the quality of my sleep and helping me make adjustments for better rest.Being a tech enthusiast and someone deeply involved in the IT sector, I appreciate the crash detection and heart rate monitoring functions. Safety is paramount, and the watch's ability to detect a potential fall and initiate an emergency call is a reassuring feature, especially when I'm out traveling or in the middle of a research project. The heart rate monitor keeps me informed about my cardiovascular health during workouts and daily activities.As someone who loves teaching and mentoring, the Apple Watch SE also helps me manage my busy schedule. The calendar notifications and reminders keep me on track for meetings with my mentees and colleagues at the lab, which is essential for our collaborative projects, such as "Collaborative sports," "Amby: Language model for middle schoolers," and "Integrate AI."Moreover, the watch seamlessly integrates with my iPhone, allowing me to respond to messages, emails, and calls without taking out my phone, which is incredibly convenient during our frequent lab meetings and while I'm on the go.In conclusion, the Apple Watch SE (2nd Gen) has become an indispensable part of my daily life. Its fitness and health-tracking features, coupled with its integration into my professional and academic activities, make it a must-have for anyone in the IT sector aiming to be a leader in future IT solutions. Whether I'm teaching React JS or exploring new states in the USA, this smartwatch has proven to be a reliable companion. Highly recommended! | J15: Electronics
A16: AEEEIOCKG5TKBOHMHNLSAGAQRHZQ | B16: PROD015 | C16: M@reBe@r | D16: 45661.145 | E16: Best watch for iOS users, itâ€™s a no-brainer! | F16: Verified Purchase | G16: 39 | H16: 5 | I16: I was always a Fitbit user for my iPhone because I thought Apple Watch was too pricey for me. I started out with the Fitbit Blaze which was fine then upgraded to the first Sense watch which was junk. It finally died on me after only 3 years and the glue didnâ€™t hold up so the face popped off. So I was in the market for a new smart watch.Finally broke down and bought this watch. Price for the SE was similar to the Fitbit.This is night and day!! If youâ€™re on the fence about which one to choose, go with the Apple Watch!!The only downside is you have to charge it daily. Youâ€™ll get used to it. Itâ€™s fine, youâ€™ll live.Itâ€™s beautiful, stylish but most of all you get all the features that mimics your phone. Youâ€™re not limited to the basics like you are with Fitbit. With the Apple Watch you can do it all so you get more bang for your buck. Donâ€™t think on it. Just get this. Itâ€™s a no-brainer. Woot! | J16: Electronics
A17: AE3JRWFDK7YKPRU5LQVQSJQWGB7A | B17: PROD016 | C17: JosÃ© A. Corleto | D17: 45661.618 | E17: Nice and affordable watch | F17: Verified Purchase | H17: 4 | I17: I bought it for my wife and sheâ€™s happy with it.As many other customers say, the battery life is not the best. It can barely last for around 18 hours despite most of the background processes are turned off. | J17: Electronics
A18: AECKACZU66B2I754RUINZDECF3AQ | B18: PROD017 | C18: Tyandra PTyandra P | D18: 45661.65 | E18: Authentic product | F18: Verified Purchase | G18: 2 | H18: 5 | I18: Iâ€™ve had it for a few months now and itâ€™s easy to set up, affordable and very convenient for me when iâ€™m at work. I love the color and size of it tooâ˜ºï¸ | J18: Electronics
A19: AHKYMAJBD6UHJMES64ZTISYKNM5A | B19: PROD018 | C19: Ricardo | D19: 45661.755 | E19: Great apple watch | F19: Verified Purchase | H19: 5 | I19: Bought this for my sister after we bough a used one that barely worked. This works perfect and my sister absolutely loves it. We got it for her birthday and she says it fits her perfect and works amazing. She said the battery life is great and it charges fine. My sister does manual labor and said the watch has taken a beating but doing really good. She loves it so much and it is a great product. I have grown fond of apple but still they need to work on some things haha. | J19: Electronics
A20: AEX3T6BZUU3X7SW3NVMRRB26BYDQ | B20: PROD019 | C20: aleciaalecia | D20: 45661.942 | E20: Great Watch | F20: Verified Purchase | H20: 5 | I20: I bought this watch for my daughter & she loves it. It has alot of great features and works well with her Iphone. It's very user-friendly & the apps are easy to navigate. The battery works efficiently and last for a long time. | J20: Electronics
A21: AEK55BORHMM5XESWCDLS3TAFSEHQ | B21: PROD020 | C21: Marie | D21: 45662.459 | E21: Apple Watch/fitness tracker | F21: Verified Purchase | H21: 5 | I21: I have had this watch for over a year super functional quality to watch is amazing. Very durable. I work out with all my wrist every day and donâ€™t even know itâ€™s on my wrist. Due to how itâ€™s very lightweight and it charges super quick at night itâ€™s charged within probably an hour. | J21: Electronics
A22: AE563QU2VOUFPWLJ266B6DHQJT5Q | B22: PROD021 | C22: Tiffany Lee Mezo | D22: 45662.763 | E22: Watch Saver | F22: Verified Purchase | H22: 5 | I22: Well, my mom was out for a walk when she fell and the watch actually called 911! I didnâ€™t know it would do this! EMS came and cleaned her wounds up. That God for this watch!!!! | J22: Electronics
A23: AEHRQQWGO6WRJNDGCXC5EUG6TNGQ | B23: PROD022 | C23: Karla | D23: 45662.914 | E23: I purchased a watch front & back cover to keep it nicer. | F23: Verified Purchase | H23: 5 | I23: Iâ€™m liking that I can change my watch bands. My other Apple Watch I couldâ€™t get the watch band on one side the button would not push in no how no way. I could actually set the watch up to my phone myself! | J23: Electronics
A24: AGAYKCP2GM6DDHHJLW6CTBWKBSMA | B24: PROD023 | C24: Tasha | D24: 45663.311 | E24: Apple Watch accessories | F24: Verified Purchase | H24: 5 | I24: Color is nice and great fit | J24: Electronics
A25: AFCZNLXHN2L3OFOETOBGK42LBBEQ | B25: PROD024 | C25: BLJL25BLJL25 | D25: 45663.495 | E25: Perfect | F25: Verified Purchase | H25: 5 | I25: Got this on sale and itâ€™s perfect. My old watch broke and was so bummed until I found this perfect replacement | J25: Electronics
A26: AEICPXK6OTUMCQPNXNOZ5MU2NXEA | B26: PROD025 | C26: ElizabethElizabeth | D26: 45663.731 | E26: It wakes me up in the morning by tapping my wrist, without waking up anyone else | F26: Verified Purchase | G26: One | H26: 5 | I26: My last watch the glass kind of chipped and started breaking so I figured to get a new watch.I think I went down as far as what features the Watch can do to this SE watch. But it still has the functions that I actually want. For example, it wakes me up when the alarm goes off; that way, it doesnâ€™t wake up anyone else because itâ€™s not beeping. Itâ€™s just tapping my wrist.I can also use the other functions that has such as answering the phone and answering texts. You can also check the weather and you can see the pictures that people sent you.There are really so many features to it that Iâ€™m not really sure that I would need the watch that has more features because this is really a good watch!I highly recommend this watch. Itâ€™s really good and it looks nice and the feature where it wakes me up without having to go off, but just tap my wrist, is the reason I actually bought this watch.I highly recommend this watch! you should get it! | J26: Electronics
A27: AHZMTCAM7PECOL2L7QZVF225VONA | B27: PROD026 | C27: Jae | D27: 45663.96 | E27: Great gift | F27: Verified Purchase | H27: 5 | I27: Got this as a gift and they loved it! Works well and looks very nice! | J27: Electronics
A28: AE4T7OL4UCDBFVWFKPEUCJR5CKKA | B28: PROD027 | C28: Amazon Customer | D28: 45664.697 | E28: you have to charge it everyday | F28: Verified Purchase | H28: 4 | I28: the battery does not last very long. | J28: Electronics
A29: AFVA2N7GIU6SSK2K26QC7JE2CI3A | B29: PROD028 | C29: Darlene Cooley | D29: 45665.528 | E29: Happy with watch | F29: Verified Purchase | H29: 5 | I29: Happy with this watch. Has all the functions I need and use. A charge usually lasts me two days. Would buy again. | J29: Electronics
A30: AHKAY36QG2ZU2ETEC7R26LDSLIHA | B30: PROD029 | C30: Summer G.Summer G. | D30: 45665.564 | E30: Satisfied | F30: Verified Purchase | G30: One | H30: 4 | I30: The media could not be loaded. The only reason I ordered it from Amazon not the official website was because the price was lower. It arrived in a perfect condition. As for the product, Iâ€™m satisfied with it just like any other Apple products. Iâ€™ve had it for a month but I donâ€™t wear it all day just because I donâ€™t like having anything on my wrist. Itâ€™s mostly for workout purposes. The only thing I donâ€™t approve of is the battery life. The battery runs out fast even when I leave it on a counter all day. But like I said, since I donâ€™t wear it often. It doesnâ€™t bother me too much. | J30: Electronics
A31: AH524CD5S6DI4M665QORBS6QJL3Q | B31: PROD030 | C31: Fattiesmama | D31: 45665.585 | E31: Exactly what we wanted | F31: Verified Purchase | H31: 5 | I31: Ordered this watch as a replacement for an old watch. It was everything we needed and arrived in a timely manner. The watch is new and sealed, it paired fine with the phone. | J31: Electronics
A32: AHRQQN36UWBMDXA7G53775PYRJRQ | B32: PROD031 | C32: Matt P. | D32: 45665.915 | E32: My daughter loves it | F32: Verified Purchase | H32: 5 | I32: Bought this for my daughter for Christmas 2023, after her wearing it pretty much everyday for a year it's still going strong and works great. She loves it. | J32: Electronics
A33: AE74NWBRHXSGMN5AWZHDGAZNMBCQ | B33: PROD032 | C33: Amazon Customer | D33: 45666.057 | E33: Love, love, love it | F33: Verified Purchase | H33: 5 | I33: I am so happy with this watch. I should have gotten it sooner. All these years with a phone, I forgot how nice it is to hear have a watch. I love seeing the temperature at a glance, and what my next appointment is. I love the ease of health monitoring, controlling music playback, and receiving messages even if Iâ€™m not near my phone.I donâ€™t care for the band, but there are endless replacement possibilities. I was thrown off by the USBC charger, but itâ€™s no big deal now. I also bought normal-USB-compatible backup chargers for my car and my office. The charging speed is good. I bought a screen protector/cover and itâ€™s already pretty banged up, so Iâ€™m glad I did. | J33: Electronics
A34: AGDJD5B3AUVK4WGEDM2S7YEKB7FA | B34: PROD033 | C34: Amazon Customer | D34: 45666.169 | E34: Okay, I'm a convert | F34: Verified Purchase | H34: 5 | I34: I really loved my Fitbit Luxe for its small size and stylish look. I didn't really need all the extras an Apple watch offers, and I didn't want to wear the big clunky Apple. But when Google took over and my last Fitbit died for the final time. it appeared that it really wasn't being supported any longer. Why did I wait so long? This watch is waaaay more than I really need, but I love it! There are lots of replacement bands available to lessen the utilitarian appearance. | J34: Electronics
A35: AHKETNWF3EFO54W2U2AGW4GGHIOA | B35: PROD034 | C35: Bretz | D35: 45666.52 | E35: Battery life | F35: Verified Purchase | H35: 4 | I35: Itâ€™s a pretty good item, the battery life just doesnâ€™t last as long as Iâ€™d expect. | J35: Electronics
A36: AHG62TLHNV6VMSHX6ZKLKK6GBQCQ | B36: PROD035 | C36: Jan | D36: 45667.19 | E36: It's OK | F36: Verified Purchase | H36: 3 | I36: This watch has some nice features: being able to receive emails and phone calls on it from your iPhone is very convenient, as is the sleep schedule/wind down feature. The wide choice of watch faces that show different information (or none at all if that's what you want) is nice to have.I had a Fitbit Charge 5 (which I opted not to replace when it died bc Fitbit seems to have reliability issues) & some of the features I loved about that watch were that it showed real-time info on your heart rate without having to click off to another screen, and it tracked SPO2 info, which this watch does not & you will have to buy a separate pulse oximeter. You will need to charge this watch every day, as opposed to every 4-5 days with a Fitbit. And the band that came with the watch kept popping off. I ended up buying a set of silicone watchbands from a third-party seller on Amazon that had a rectangular stud instead of a round one & that solved the popping-off problem.I'm still trying to figure out the Activity app on this watch bc i don't find it easy to follow & don't feel that it provides good real-time info on your activity levels, but maybe that's just bc I haven't figured it all out yet.It seems like this watch is really more for people who want the convenience of having a mini-iPhone on their wrist than for people who want to track their health and fitness. | J36: Electronics
A37: AGOEB7I7DMZOWRJH4H2VTGE7AWYQ | B37: PROD036 | C37: SarahSarah | D37: 45667.486 | E37: Easier than going to the store. | F37: Verified Purchase | G37: 23 | H37: 5 | I37: When my original Apple Watch started having problems, I thought I was going to have to go wait in store to buy a new watch but when I found this one on Amazon, I thought it would be too good to be true. This watch is exactly the same as what you would buy in store, but without the wait. I have always liked this Apple Watch because I've never needed the newest one. The functionality, sound quality, Watch quality, and weight were always some of my favorite things about it. I love that this one came with the more cream/rose colored band. But for work I usually just used my old band so I donâ€™t damage the new one. If you want an Apple Watch at a good price and donâ€™t need the newest one, I would suggest this one. I like the price of it a lot better too. | J37: Electronics
A38: AHRLNVY3M6VKWNYR5J6OZGYHHUBA | B38: PROD037 | C38: Sandy | D38: 45667.626 | E38: 1st time Apple Watch wearer! | F38: Verified Purchase | H38: 5 | I38: And I love it! | J38: Electronics
A39: AFCVISYWC2AVDOXPZKNIB6PUHRMQ | B39: PROD038 | C39: Roland Frymire | D39: 45667.713 | E39: Great little watch except for one important thing | F39: Verified Purchase | G39: 5 | H39: 4 | I39: Iâ€™ve owned a couple of these Apple watches that are great products with the exception of one major problem. I have also purchased non-apple watches that cost much less that have had a much longer battery life than the Apple Watch. I donâ€™t understand why the Apple Watch has a pathetic battery life wherein the much cheaper watches are Incredibly proficient in their battery life. The battery life for an Apple Watch is on the average is 24 hours wherein the other much less expensive non-Apple watches can go for days or even weeks. Shame on Apple. | J39: Electronics
A40: AGXQFILAA7LDXARFEIYWDGGBWAFQ | B40: PROD039 | C40: SunDevil03 | D40: 45667.973 | E40: Fiance Loves It | F40: Verified Purchase | G40: One | H40: 5 | I40: My fiance has never had a smart watch and she would often talk about how cool it would be. But she doesn't make a ton of money so it's always been a bit of a pipe dream. Well her birthday came around and this watch was at a great price, so I had to pick it up for her. She absolutely loves it. Perfect functionality. It's not too big, but still big enough to be useful.Personally I'm a Samsung guy and I've got a Galaxy Watch that I love, but she sure loves her Apple Watch and so far it appears to be a big winner. | J40: Electronics
...

Sheet Data_cleaning
A1: User_id | B1: Product_ID | C1: rating | D1: date/timestamp | E1: category | F1: review | G1: Is_complete | H1: Valid_rating | I1: Rating_category | J1: Standardized user_id | K1: User Type | L1: Year | M1: Month | N1: Month name | O1: Quarter
A2: AH5M24Z73ZHQGN77WA3JT3Q7TEBQ | B2: PROD001 | C2: 5 | D2: 45658.158 | E2: kitchen | F2: NUWAVE, GRILL IS PRETTY GOOD SO FAR | G2: =IF(AND(A2<>"", B2<>"", C2<>"", D2<>"", E2<>"", F2<>""), "Complete", "Incomplete") -> Complete | H2: =IF(AND(C2>=1, C2<=5), "Valid", "Invalid") -> Valid | I2: =IF(C2>=4, "High(4-5)", IF(C2>=3, "Medium(3)", "Low(1-2)")) -> High(4-5) | J2: =TRIM(UPPER(A2)) -> AH5M24Z73ZHQGN77WA3JT3Q7TEBQ | K2: =IF(COUNTIF(Data_cleaning!$A:$A, A2)>10, "Power User", IF(COUNTIF(Data_cleaning!$A:$A, A2)>5, "Regular User", IF(COUNTIF(Data_cleaning!$A:$A, A2)>1, "Casual User", "One-Time User"))) -> One-Time User | L2: =YEAR(Table4[[#This Row],[date/timestamp]]) -> 2025 | M2: =MONTH(Table4[[#This Row],[date/timestamp]]) -> 1 | N2: =TEXT(Table4[[#This Row],[date/timestamp]], "MMMM") -> January | O2: ="Q"&INT((MONTH(D2)-1)/3)+1 -> Q1
A3: AFI7ALURI5CPDT4V7CUXZXLNFDVA | B3: PROD002 | C3: 5 | D3: 45658.222 | E3: kitchen | F3: Game changer | G3: =IF(AND(A3<>"", B3<>"", C3<>"", D3<>"", E3<>"", F3<>""), "Complete", "Incomplete") -> Complete | H3: =IF(AND(C3>=1, C3<=5), "Valid", "Invalid") -> Valid | I3: =IF(C3>=4, "High(4-5)", IF(C3>=3, "Medium(3)", "Low(1-2)")) -> High(4-5) | J3: =TRIM(UPPER(A3)) -> AFI7ALURI5CPDT4V7CUXZXLNFDVA | K3: =IF(COUNTIF(Data_cleaning!$A:$A, A3)>10, "Power User", IF(COUNTIF(Data_cleaning!$A:$A, A3)>5, "Regular User", IF(COUNTIF(Data_cleaning!$A:$A, A3)>1, "Casual User", "One-Time User"))) -> One-Time User | L3: =YEAR(Table4[[#This Row],[date/timestamp]]) -> 2025 | M3: =MONTH(Table4[[#This Row],[date/timestamp]]) -> 1 | N3: =TEXT(Table4[[#This Row],[date/timestamp]], "MMMM") -> January | O3: ="Q"&INT((MONTH(D3)-1)/3)+1 -> Q1
A4: AENH6LSB6BM7XLPEYUL43WBOD6JA | B4: PROD002 | C4: 4 | D4: 45658.447 | E4: kitchen | F4: More Than Meets My Needs | G4: =IF(AND(A4<>"", B4<>"", C4<>"", D4<>"", E4<>"", F4<>""), "Complete", "Incomplete") -> Complete | H4: =IF(AND(C4>=1, C4<=5), "Valid", "Invalid") -> Valid | I4: =IF(C4>=4, "High(4-5)", IF(C4>=3, "Medium(3)", "Low(1-2)")) -> High(4-5) | J4: =TRIM(UPPER(A4)) -> AENH6LSB6BM7XLPEYUL43WBOD6JA | K4: =IF(COUNTIF(Data_cleaning!$A:$A, A4)>10, "Power User", IF(COUNTIF(Data_cleaning!$A:$A, A4)>5, "Regular User", IF(COUNTIF(Data_cleaning!$A:$A, A4)>1, "Casual User", "One-Time User"))) -> One-Time User | L4: =YEAR(Table4[[#This Row],[date/timestamp]]) -> 2025 | M4: =MONTH(Table4[[#This Row],[date/timestamp]]) -> 1 | N4: =TEXT(Table4[[#This Row],[date/timestamp]], "MMMM") -> January | O4: ="Q"&INT((MONTH(D4)-1)/3)+1 -> Q1
A5: AHFAAT5CJ6IIGIURHFBICP44ZHVA | B5: PROD002 | C5: 5 | D5: 45658.657 | E5: kitchen | F5: Great machine and incredible customer support! | G5: =IF(AND(A5<>"", B5<>"", C5<>"", D5<>"", E5<>"", F5<>""), "Complete", "Incomplete") -> Complete | H5: =IF(AND(C5>=1, C5<=5), "Valid", "Invalid") -> Valid | I5: =IF(C5>=4, "High(4-5)", IF(C5>=3, "Medium(3)", "Low(1-2)")) -> High(4-5) | J5: =TRIM(UPPER(A5)) -> AHFAAT5CJ6IIGIURHFBICP44ZHVA | K5: =IF(COUNTIF(Data_cleaning!$A:$A, A5)>10, "Power User", IF(COUNTIF(Data_cleaning!$A:$A, A5)>5, "Regular User", IF(COUNTIF(Data_cleaning!$A:$A, A5)>1, "Casual User", "One-Time User"))) -> One-Time User | L5: =YEAR(Table4[[#This Row],[date/timestamp]]) -> 2025 | M5: =MONTH(Table4[[#This Row],[date/timestamp]]) -> 1 | N5: =TEXT(Table4[[#This Row],[date/timestamp]], "MMMM") -> January | O5: ="Q"&INT((MONTH(D5)-1)/3)+1 -> Q1
A6: AG4UMTWF2QN3BRDCSNVXTGZTPCAA | B6: PROD002 | C6: 5 | D6: 45658.837 | E6: kitchen | F6: Love it | G6: =IF(AND(A6<>"", B6<>"", C6<>"", D6<>"", E6<>"", F6<>""), "Complete", "Incomplete") -> Complete | H6: =IF(AND(C6>=1, C6<=5), "Valid", "Invalid") -> Valid | I6: =IF(C6>=4, "High(4-5)", IF(C6>=3, "Medium(3)", "Low(1-2)")) -> High(4-5) | J6: =TRIM(UPPER(A6)) -> AG4UMTWF2QN3BRDCSNVXTGZTPCAA | K6: =IF(COUNTIF(Data_cleaning!$A:$A, A6)>10, "Power User", IF(COUNTIF(Data_cleaning!$A:$A, A6)>5, "Regular User", IF(COUNTIF(Data_cleaning!$A:$A, A6)>1, "Casual User", "One-Time User"))) -> One-Time User | L6: =YEAR(Table4[[#This Row],[date/timestamp]]) -> 2025 | M6: =MONTH(Table4[[#This Row],[date/timestamp]]) -> 1 | N6: =TEXT(Table4[[#This Row],[date/timestamp]], "MMMM") -> January | O6: ="Q"&INT((MONTH(D6)-1)/3)+1 -> Q1
A7: AHO5TWX2UUDF22I2XOW4SZN2GDRQ | B7: PROD002 | C7: 5 | D7: 45658.996 | E7: kitchen | F7: Works great! | G7: =IF(AND(A7<>"", B7<>"", C7<>"", D7<>"", E7<>"", F7<>""), "Complete", "Incomplete") -> Complete | H7: =IF(AND(C7>=1, C7<=5), "Valid", "Invalid") -> Valid | I7: =IF(C7>=4, "High(4-5)", IF(C7>=3, "Medium(3)", "Low(1-2)")) -> High(4-5) | J7: =TRIM(UPPER(A7)) -> AHO5TWX2UUDF22I2XOW4SZN2GDRQ | K7: =IF(COUNTIF(Data_cleaning!$A:$A, A7)>10, "Power User", IF(COUNTIF(Data_cleaning!$A:$A, A7)>5, "Regular User", IF(COUNTIF(Data_cleaning!$A:$A, A7)>1, "Casual User", "One-Time User"))) -> One-Time User | L7: =YEAR(Table4[[#This Row],[date/timestamp]]) -> 2025 | M7: =MONTH(Table4[[#This Row],[date/timestamp]]) -> 1 | N7: =TEXT(Table4[[#This Row],[date/timestamp]], "MMMM") -> January | O7: ="Q"&INT((MONTH(D7)-1)/3)+1 -> Q1
A8: AFKZUIF6G6FKXDFO22NL5W3ZLHUQ | B8: PROD001 | C8: 5 | D8: 45659.039 | E8: kitchen | F8: Quiet! Hot! It has Rotisserie!! | G8: =IF(AND(A8<>"", B8<>"", C8<>"", D8<>"", E8<>"", F8<>""), "Complete", "Incomplete") -> Complete | H8: =IF(AND(C8>=1, C8<=5), "Valid", "Invalid") -> Valid | I8: =IF(C8>=4, "High(4-5)", IF(C8>=3, "Medium(3)", "Low(1-2)")) -> High(4-5) | J8: =TRIM(UPPER(A8)) -> AFKZUIF6G6FKXDFO22NL5W3ZLHUQ | K8: =IF(COUNTIF(Data_cleaning!$A:$A, A8)>10, "Power User", IF(COUNTIF(Data_cleaning!$A:$A, A8)>5, "Regular User", IF(COUNTIF(Data_cleaning!$A:$A, A8)>1, "Casual User", "One-Time User"))) -> One-Time User | L8: =YEAR(Table4[[#This Row],[date/timestamp]]) -> 2025 | M8: =MONTH(Table4[[#This Row],[date/timestamp]]) -> 1 | N8: =TEXT(Table4[[#This Row],[date/timestamp]], "MMMM") -> January | O8: ="Q"&INT((MONTH(D8)-1)/3)+1 -> Q1
A9: AF44IYYKVBHBUNKQEICMO4T7MJ6Q | B9: PROD001 | C9: 5 | D9: 45659.26 | E9: kitchen | F9: Good for cheese burgers | G9: =IF(AND(A9<>"", B9<>"", C9<>"", D9<>"", E9<>"", F9<>""), "Complete", "Incomplete") -> Complete | H9: =IF(AND(C9>=1, C9<=5), "Valid", "Invalid") -> Valid | I9: =IF(C9>=4, "High(4-5)", IF(C9>=3, "Medium(3)", "Low(1-2)")) -> High(4-5) | J9: =TRIM(UPPER(A9)) -> AF44IYYKVBHBUNKQEICMO4T7MJ6Q | K9: =IF(COUNTIF(Data_cleaning!$A:$A, A9)>10, "Power User", IF(COUNTIF(Data_cleaning!$A:$A, A9)>5, "Regular User", IF(COUNTIF(Data_cleaning!$A:$A, A9)>1, "Casual User", "One-Time User"))) -> One-Time User | L9: =YEAR(Table4[[#This Row],[date/timestamp]]) -> 2025 | M9: =MONTH(Table4[[#This Row],[date/timestamp]]) -> 1 | N9: =TEXT(Table4[[#This Row],[date/timestamp]], "MMMM") -> January | O9: ="Q"&INT((MONTH(D9)-1)/3)+1 -> Q1
A10: AGTVNHEOZCRUASEIU2QX6JBVWNCQ | B10: PROD002 | C10: 5 | D10: 45659.377 | E10: kitchen | F10: oven | G10: =IF(AND(A10<>"", B10<>"", C10<>"", D10<>"", E10<>"", F10<>""), "Complete", "Incomplete") -> Complete | H10: =IF(AND(C10>=1, C10<=5), "Valid", "Invalid") -> Valid | I10: =IF(C10>=4, "High(4-5)", IF(C10>=3, "Medium(3)", "Low(1-2)")) -> High(4-5) | J10: =TRIM(UPPER(A10)) -> AGTVNHEOZCRUASEIU2QX6JBVWNCQ | K10: =IF(COUNTIF(Data_cleaning!$A:$A, A10)>10, "Power User", IF(COUNTIF(Data_cleaning!$A:$A, A10)>5, "Regular User", IF(COUNTIF(Data_cleaning!$A:$A, A10)>1, "Casual User", "One-Time User"))) -> One-Time User | L10: =YEAR(Table4[[#This Row],[date/timestamp]]) -> 2025 | M10: =MONTH(Table4[[#This Row],[date/timestamp]]) -> 1 | N10: =TEXT(Table4[[#This Row],[date/timestamp]], "MMMM") -> January | O10: ="Q"&INT((MONTH(D10)-1)/3)+1 -> Q1
A11: AEZMHCTOR4XWPQJJEP47UBY2G4UA | B11: PROD010 | C11: 4 | D11: 45660.153 | E11: kitchen | F11: Good | G11: =IF(AND(A11<>"", B11<>"", C11<>"", D11<>"", E11<>"", F11<>""), "Complete", "Incomplete") -> Complete | H11: =IF(AND(C11>=1, C11<=5), "Valid", "Invalid") -> Valid | I11: =IF(C11>=4, "High(4-5)", IF(C11>=3, "Medium(3)", "Low(1-2)")) -> High(4-5) | J11: =TRIM(UPPER(A11)) -> AEZMHCTOR4XWPQJJEP47UBY2G4UA | K11: =IF(COUNTIF(Data_cleaning!$A:$A, A11)>10, "Power User", IF(COUNTIF(Data_cleaning!$A:$A, A11)>5, "Regular User", IF(COUNTIF(Data_cleaning!$A:$A, A11)>1, "Casual User", "One-Time User"))) -> One-Time User | L11: =YEAR(Table4[[#This Row],[date/timestamp]]) -> 2025 | M11: =MONTH(Table4[[#This Row],[date/timestamp]]) -> 1 | N11: =TEXT(Table4[[#This Row],[date/timestamp]], "MMMM") -> January | O11: ="Q"&INT((MONTH(D11)-1)/3)+1 -> Q1
A12: AFGOHTTJWRAYHJQKZZULDJID5ADQ | B12: PROD011 | C12: 5 | D12: 45660.29 | E12: Electronics | F12: Great tool for busy mom | G12: =IF(AND(A12<>"", B12<>"", C12<>"", D12<>"", E12<>"", F12<>""), "Complete", "Incomplete") -> Complete | H12: =IF(AND(C12>=1, C12<=5), "Valid", "Invalid") -> Valid | I12: =IF(C12>=4, "High(4-5)", IF(C12>=3, "Medium(3)", "Low(1-2)")) -> High(4-5) | J12: =TRIM(UPPER(A12)) -> AFGOHTTJWRAYHJQKZZULDJID5ADQ | K12: =IF(COUNTIF(Data_cleaning!$A:$A, A12)>10, "Power User", IF(COUNTIF(Data_cleaning!$A:$A, A12)>5, "Regular User", IF(COUNTIF(Data_cleaning!$A:$A, A12)>1, "Casual User", "One-Time User"))) -> One-Time User | L12: =YEAR(Table4[[#This Row],[date/timestamp]]) -> 2025 | M12: =MONTH(Table4[[#This Row],[date/timestamp]]) -> 1 | N12: =TEXT(Table4[[#This Row],[date/timestamp]], "MMMM") -> January | O12: ="Q"&INT((MONTH(D12)-1)/3)+1 -> Q1
A13: AFFUJJPQEWVDXYGSKC3SLMIIU75Q | B13: PROD012 | C13: 5 | D13: 45660.524 | E13: Electronics | F13: Amazing, my favorite purchase | G13: =IF(AND(A13<>"", B13<>"", C13<>"", D13<>"", E13<>"", F13<>""), "Complete", "Incomplete") -> Complete | H13: =IF(AND(C13>=1, C13<=5), "Valid", "Invalid") -> Valid | I13: =IF(C13>=4, "High(4-5)", IF(C13>=3, "Medium(3)", "Low(1-2)")) -> High(4-5) | J13: =TRIM(UPPER(A13)) -> AFFUJJPQEWVDXYGSKC3SLMIIU75Q | K13: =IF(COUNTIF(Data_cleaning!$A:$A, A13)>10, "Power User", IF(COUNTIF(Data_cleaning!$A:$A, A13)>5, "Regular User", IF(COUNTIF(Data_cleaning!$A:$A, A13)>1, "Casual User", "One-Time User"))) -> One-Time User | L13: =YEAR(Table4[[#This Row],[date/timestamp]]) -> 2025 | M13: =MONTH(Table4[[#This Row],[date/timestamp]]) -> 1 | N13: =TEXT(Table4[[#This Row],[date/timestamp]], "MMMM") -> January | O13: ="Q"&INT((MONTH(D13)-1)/3)+1 -> Q1
... A1444: AE5KYF2QVH6VMX4F4FAZS57E2FXQ | B1444: PROD1497 | C1444: 5 | D1444: 45967.847 | E1444: Cloth and accessaries | F1444: Un poco liviana, pero parece buena. | G1444: =IF(AND(A1444<>"", B1444<>"", C1444<>"", D1444<>"", E1444<>"", F1444<>""), "Complete", "Incomplete") -> Complete | H1444: =IF(AND(C1444>=1, C1444<=5), "Valid", "Invalid") -> Valid | I1444: =IF(C1444>=4, "High(4-5)", IF(C1444>=3, "Medium(3)", "Low(1-2)")) -> High(4-5) | J1444: =TRIM(UPPER(A1444)) -> AE5KYF2QVH6VMX4F4FAZS57E2FXQ | K1444: =IF(COUNTIF(Data_cleaning!$A:$A, A1444)>10, "Power User", IF(COUNTIF(Data_cleaning!$A:$A, A1444)>5, "Regular User", IF(COUNTIF(Data_cleaning!$A:$A, A1444)>1, "Casual User", "One-Time User"))) -> One-Time User | L1444: =YEAR(Table4[[#This Row],[date/timestamp]]) -> 2025 | M1444: =MONTH(Table4[[#This Row],[date/timestamp]]) -> 11 | N1444: =TEXT(Table4[[#This Row],[date/timestamp]], "MMMM") -> November | O1444: ="Q"&INT((MONTH(D1444)-1)/3)+1 -> Q4

Sheet Analysis
A1: OVERALL STATISTICS | E1: TOP ACTIVE USERS | I1: COUNT BY SEGMENT | L1: REVIEWS OVERTIME
A2: Metric | B2: Formula | C2: Result | E2: User id | F2: {=INDEX(Data_cleaning!A2:A1500,MATCH(MAX(COUNTIF(Data_cleaning!A2:A1500,Data_cleaning!A2:A1500)),COUNTIF(Data_cleaning!A2:A1500,Data_cleaning!A2:A1500),0))} -> AECDXBV7YXUT7T2XYKIOTAMMFBKA | I2: Power users | J2: =COUNTIF(Data_cleaning!K:K, "Power User") -> 0 | L2: Row Labels | M2: Count of User_id | O2: GROWTH RATE
A3: Total reviews | B3: =COUNTA(Data_cleaning! A:A)-1' | C3: =COUNTA(Data_cleaning!A:A)-1 -> 1443 | E3: Review count | F3: =COUNTIF(Data_cleaning!A:A, A616) -> 1 | I3: Regular users | J3: =COUNTIF(Data_cleaning!K:K, "Regular User") -> 0 | L3: 2025 | O3: 0
A4: Total users | B4: =SUMPRODUCT(1/COUNTIF(Data_Cleaning!A:A,Data_Cleaning!A:A))` | C4: =SUMPRODUCT((Data_cleaning!A2:A1444<>"")/COUNTIF(Data_cleaning!A2:A1444,Data_cleaning!A2:A1444&"")) -> 1420 | I4: Casual users | J4: =COUNTIF(Data_cleaning!K:K, "Casual User") -> 46 | L4: 1 | M4: 141 | O4: =GETPIVOTDATA("User_id",$L$2,"Year",2025,"Month",2)-GETPIVOTDATA("User_id",$L$2,"Year",2025,"Month",1)/GETPIVOTDATA("User_id",$L$2,"Year",2025,"Month",1) -> 124
A5: Total products | B5: =SUMPRODUCT(/COUNTIF(Data_Cleaning!B:B,Data_Cleaning!B:B))` | C5: =SUMPRODUCT((Data_cleaning!B2:B1444<>"")/COUNTIF(Data_cleaning!B2:B1444,Data_cleaning!B2:B1444&"")) -> 1406 | I5: One time users | J5: =COUNTIF(Data_cleaning!K:K, "One-Time User") -> 1397 | L5: 2 | M5: 125 | O5: =GETPIVOTDATA("User_id",$L$2,"Year",2025,"Month",3)-GETPIVOTDATA("User_id",$L$2,"Year",2025,"Month",2)/GETPIVOTDATA("User_id",$L$2,"Year",2025,"Month",2) -> 142
A6: Average rating | B6: `=AVERAGE(Data_Cleaning!C:C)` | C6: =ROUND(AVERAGE(Data_cleaning!C:C), 2) -> 4.56 | L6: 3 | M6: 143 | O6: =GETPIVOTDATA("User_id",$L$2,"Year",2025,"Month",4)-GETPIVOTDATA("User_id",$L$2,"Year",2025,"Month",3)/GETPIVOTDATA("User_id",$L$2,"Year",2025,"Month",3) -> 149
A7: Rating standard deviation | B7: `=STDEV.P(Data_Cleaning!C:C)` | C7: =ROUND(_xlfn.STDEV.P(Data_cleaning!C:C), 2) -> 0.79 | E7: overall average rating: | L7: 4 | M7: 150 | O7: =GETPIVOTDATA("User_id",$L$2,"Year",2025,"Month",5)-GETPIVOTDATA("User_id",$L$2,"Year",2025,"Month",4)/GETPIVOTDATA("User_id",$L$2,"Year",2025,"Month",4) -> 100
E8: =ROUND(AVERAGE(Data_cleaning!C2:C1500), 2) -> 4.56 | L8: 5 | M8: 101 | O8: =GETPIVOTDATA("User_id",$L$2,"Year",2025,"Month",6)-GETPIVOTDATA("User_id",$L$2,"Year",2025,"Month",5)/GETPIVOTDATA("User_id",$L$2,"Year",2025,"Month",5) -> 154
L9: 6 | M9: 155 | O9: =GETPIVOTDATA("User_id",$L$2,"Year",2025,"Month",7)-GETPIVOTDATA("User_id",$L$2,"Year",2025,"Month",6)/GETPIVOTDATA("User_id",$L$2,"Year",2025,"Month",6) -> 140
L10: 7 | M10: 141 | O10: =GETPIVOTDATA("User_id",$L$2,"Year",2025,"Month",8)-GETPIVOTDATA("User_id",$L$2,"Year",2025,"Month",7)/GETPIVOTDATA("User_id",$L$2,"Year",2025,"Month",7) -> 151
A11: USER BEHAVIOUR ANALYSIS | D11: PRODUCT POPULARITY | H11: RATING DISTRIBUTION ANALYSIS | L11: 8 | M11: 152 | O11: =GETPIVOTDATA("User_id",$L$2,"Year",2025,"Month",9)-GETPIVOTDATA("User_id",$L$2,"Year",2025,"Month",8)/GETPIVOTDATA("User_id",$L$2,"Year",2025,"Month",8) -> 157
A12: Row Labels | B12: Count of Product_ID | D12: Row Labels | E12: Average of rating | F12: Count of rating2 | H12: Rating | I12: Count | J12: Percentage | L12: 9 | M12: 158 | O12: =GETPIVOTDATA("User_id",$L$2,"Year",2025,"Month",10)-GETPIVOTDATA("User_id",$L$2,"Year",2025,"Month",9)/GETPIVOTDATA("User_id",$L$2,"Year",2025,"Month",9) -> 150
A13: AHZOS45H5WKR7B2PWESHKQFB75SQ | B13: 2 | D13: PROD110 | E13: 5 | F13: 6 | H13: 5 stars | I13: =COUNTIF(Data_cleaning!C:C, 5) -> 994 | J13: =ROUND(I13/I18, 2) -> 0.69 | L13: 10 | M13: 151 | O13: =GETPIVOTDATA("User_id",$L$2,"Year",2025,"Month",11)-GETPIVOTDATA("User_id",$L$2,"Year",2025,"Month",10)/GETPIVOTDATA("User_id",$L$2,"Year",2025,"Month",11) -> 20.192308
A14: AHXONVJXS6KFLSBYAWMQYAB5P6JQ | B14: 2 | D14: PROD002 | E14: 4.8333333 | F14: 6 | H14: 4 stars | I14: =COUNTIF(Data_cleaning!C:C, 4) -> 325 | J14: =ROUND(I14/I18, 2) -> 0.23 | L14: 11 | M14: 26
A15: AHUV6JS3SNZFQNQFXUDKBA72DNSQ | B15: 2 | D15: PROD010 | E15: 4.7142857 | F15: 7 | H15: 3 stars | I15: =COUNTIF(Data_cleaning!C:C, 3) -> 84 | J15: =ROUND(I15/I18, 2) -> 0.06 | L15: Grand Total | M15: 1443
A16: AHG5QM4MKOFCXJWVDVWNLF42S2WQ | B16: 2 | D16: PROD1477 | E16: 4.5714286 | F16: 7 | H16: 2 stars | I16: =COUNTIF(Data_cleaning!C:C, 2) -> 17 | J16: =ROUND(I16/I18, 2) -> 0.01
A17: AHJ64Z5RDZCOUICREXSICDIUMROA | B17: 2 | D17: PROD012 | E17: 4.5 | F17: 6 | H17: 1 star | I17: =COUNTIF(Data_cleaning!C:C, 1) -> 23 | J17: =ROUND(I17/I18, 2) -> 0.02
A18: AHJMUF7CPNEJZZUXVCAK7KQRHI6A | B18: 2 | D18: Grand Total | E18: 4.71875 | F18: 32 | H18: TOTAL | I18: =SUM(I13,I14,I15,I16,I17) -> 1443
A19: AGRFRPTYNXGE3CGAIO7ZENQBUZWA | B19: 2
A20: AGEOPVR2EZFXK4VKO4J5AE6LORIA | B20: 2 | L20: AVERAGE RATING TREND
A21: AGTSK6Q7WW6L57XNLK74RFMLIMDA | B21: 2 | L21: Row Labels | M21: Average of rating
A22: AG5VTTQKNBBVOCRRFD7SUISNIEOQ | B22: 2 | D22: MOST REVIWED PRODUCTS | L22: 2025 | M22: 4.5592516
A23: AGLZY6EFUHINYSW7LPU7HNWBFIXA | B23: 2 | D23: Product_id | E23: {=INDEX(Data_cleaning!B2:B1500, MATCH(MAX(COUNTIF(Data_cleaning!B2:B1500, Data_cleaning!B2:B1500)), COUNTIF(Data_cleaning!B2:B1500, Data_cleaning!B2:B1500), 0))} -> PROD010 | F23: {=INDEX(Data_cleaning!B1413:B1444, MATCH(MAX(COUNTIF(Data_cleaning!B1413:B1444, Data_cleaning!B1413:B1444)), COUNTIF(Data_cleaning!B1413:B1444, Data_cleaning!B1413:B1444), 0))} -> PROD1477 | G23: {=INDEX(Data_cleaning!B13:B46, MATCH(MAX(COUNTIF(Data_cleaning!B13:B46, Data_cleaning!B13:B46)), COUNTIF(Data_cleaning!B13:B46, Data_cleaning!B13:B46), 0))} -> PROD012 | H23: {=INDEX(Data_cleaning!B111:B116, MATCH(MAX(COUNTIF(Data_cleaning!B111:B116, Data_cleaning!B111:B116)), COUNTIF(Data_cleaning!B111:B116, Data_cleaning!B111:B116), 0))} -> PROD110 | L23: Q1 | M23: 4.6381418
A24: AF62RCQHBHLR7RTVQ3RXW7PFZAUA | B24: 2 | D24: Review count | E24: =COUNTIF(Data_cleaning!B:B, Analysis!E23) -> 7 | F24: =COUNTIF(Data_cleaning!B:B, Analysis!F23) -> 7 | G24: =COUNTIF(Data_cleaning!B:B, Analysis!G23) -> 6 | H24: =COUNTIF(Data_cleaning!B:B, Analysis!H23) -> 6 | L24: Q2 | M24: 4.4729064
A25: AFLO7QKN3WVVES5ASJ5PBDHMKZLQ | B25: 2 | D25: Average rating | E25: =ROUND(AVERAGEIF(Data_cleaning!B:B, E23, Data_cleaning!C:C), 2) -> 4.71 | F25: =ROUND(AVERAGEIF(Data_cleaning!B:B, F23, Data_cleaning!C:C), 2) -> 4.57 | G25: =ROUND(AVERAGEIF(Data_cleaning!B:B, G23, Data_cleaning!C:C), 2) -> 4.5 | H25: =ROUND(AVERAGEIF(Data_cleaning!B:B, H23, Data_cleaning!C:C), 2) -> 5 | L25: Q3 | M25: 4.5831486
A26: AFJAP2RUXWCRIF356GGACRNQLFBA | B26: 2 | L26: Q4 | M26: 4.5141243
A27: AET6PNHHRUU54WP4OFZHYAU7KBKA | B27: 2 | D27: RATING BIAS ANALYSIS | L27: Grand Total | M27: 4.5592516
A28: AEGUBOG4HFKND2TYI7FMSJRCLYRQ | B28: 2 | D28: Positive bias (4-5) | E28: =ROUND(COUNTIFS(Data_cleaning!C:C, ">=4")/ COUNTA(Data_cleaning!C:C), 2) -> 0.91
A29: AEGI7HRSGXLKABXRNEZXHRSFIHKA | B29: 2 | D29: Negative bias (1-2) | E29: =ROUND(COUNTIFS(Data_cleaning!C:C, "<=2")/ COUNTA(Data_cleaning!C:C), 2) -> 0.03
A30: AE3PNVS6M2VT2ULP6PAYISVOKXAQ | B30: 2
A31: AEIWLJG5KA6GRV66IRCCGUEUP73A | B31: 2
A32: AECDXBV7YXUT7T2XYKIOTAMMFBKA | B32: 2 | D32: PRODUCT CO-OCCURRENCE
A33: AEUJ53NKXU75BT6LVFDQSOAZIJBQ | B33: 2 | D33: =SUMPRODUCT((Data_cleaning!$A:$A=Data_cleaning!A3)*(Data_cleaning!$B:$B=Data_cleaning!B3)*(Data_cleaning!$B:$B=Data_cleaning!B4)) -> 1
A34: AEFVTTFB7NFHCAZVLUULL3YC7WMA | B34: 2
A35: AF2BLE54TEMGZ546U763ZHZRXC4A | B35: 2
A36: AHRQQN36UWBMDXA7G53775PYRJRQ | B36: 1
A37: AHMUR6CSCHC2PA6YHLQL6TGCZKUA | B37: 1
A38: AH4IYTPAALBRN5P2U7NE3JBB6TRQ | B38: 1
A39: AH4L6S323U6DZDT2NF6KJJRRSVLQ | B39: 1
A40: AHP7T6TYPYEITN3VY5EVZQKIVS2A | B40: 1
...

Sheet Dashboard
A1: USER REVIEW AND ENGAGEMENT ANALYSIS DASHBOARD
A3: Total Reviews | B3: Active Users | C3: Products Rated | D3: Avg Rating
A4: =COUNTA(Data_cleaning!A:A)-1 -> 1443 | B4: =SUMPRODUCT((Data_cleaning!A2:A1444<>"")/COUNTIF(Data_cleaning!A2:A1444,Data_cleaning!A2:A1444&"")) -> 1420 | C4: =SUMPRODUCT((Data_cleaning!B2:B1444<>"")/COUNTIF(Data_cleaning!B2:B1444,Data_cleaning!B2:B1444&"")) -> 1406 | D4: =TEXT(AVERAGE(Data_cleaning!C2:C1444),"0.0")&" ⭐" -> 4.6 ⭐
A33: Most Reviewed Products
A34: Product_id | B34: Avg rating | C34: Review count | D34: Recommendation
A35: PROD010 | B35: 4.71 | C35: 7 | D35: =IF(AND(B35>=4, C35>=5), "Recommended", "") -> Recommended
A36: PROD1477 | B36: 4.57 | C36: 7 | D36: =IF(AND(B36>=4, C36>=5), "Recommended", "") -> Recommended
A37: PROD012 | B37: 4.5 | C37: 6 | D37: =IF(AND(B37>=4, C37>=5), "Recommended", "") -> Recommended
A38: PROD110 | B38: 5 | C38: 6 | D38: =IF(AND(B38>=4, C38>=5), "Recommended", "") -> Recommended
A41: INSIGHTS
A42: {="The average rating is " & TEXT(AVERAGE(Data_cleaning!C:C),"0.00") & CHAR(10) & "with " & TEXT(COUNTIFS(Data_cleaning!C:C,">=4")/COUNTA(Data_cleaning!C:C),"0%") & " of reviews being 4+ stars, indicating positive user sentiment."} -> The average rating is 4.56 with 91% of reviews being 4+ stars, indicating positive user sentiment.
A43: Power users contribute 0% of all the reviews
A44: 46 casual users contribute 3% of all the reviews
A45: 1397 one-time users contribute 97% of all the reviews

Sheet Documentation
A1: PROJECT DOCUMENATION
A3: Project Overview
A4: Project Title: | B4: User Review and Engagement Analysis
A5: Created by: | B5: Akinyemi Aminat
A6: Date: | B6: 45911
A7: Dataset source: | B7: https://cseweb.ucsd.edu/jmcauley/datasets.html
A8: Data size | B8: =Analysis!C3&" reviews" -> 1443 reviews
A9: Tools used | B9: Microsoft Excel
A12: Data Dictionary
A13: Column name | B13: Description | C13: Data type | D13: Example
A14: User_id | B14: Unique user identifier | C14: Text | D14: userwerts
A15: Product_id | B15: unique product identifier | C15: Text | D15: PROD112
A16: Rating | B16: User rating | C16: Number | D16: 4
A17: Date | B17: Review date | C17: Date | D17: 45658
A18: Month | B18: Extracted year | C18: Number | D18: 3
A19: Year | B19: extracted month | C19: Number | D19: 2024
A20: Month name | B20: month name | C20: Text | D20: January
A21: Rating category | B21: rating category | C21: Text | D21: High
A22: Quarter | B22: quarter of the year | C22: Text | D22: Q1
A23: Review | B23: User comment | C23: Text | D23: very good
A25: Workbook structure
A26: Raw_data | B26: Original dataset
A27: Data_cleaning | B27: cleaned dataset with extra columns for analysis
A28: Analysis | B28: calculations, pivot tables, and statistical analysis.
A29: Dashboard | B29: Visual presentation with charts and metrics
A30: Documentation | B30: project notes
A32: KEY FINDINGS
A33: Rating pattern:
A34: Average rating across all products is 4.56 stars
A35: 0.91% of the reviews are positive
A36: 0.03% of the reviews are negative
A37: The most common rating is 5 stars
A38: the least common rating is 1 star
A40: User Behaviour:
A41: The total unique users: 1443
A42: power users contribute 0% of all the ratings
A43: Casual users contribute 3% of all the ratings
A44: One-time users contribute 97% of all the ratings
... A50: Four products meet the criteria 4+ stars and 5+ reviews
